2019-10-17 16:31:54,417 ERROR: Exception on /user/user1 [GET] [in c:\users\zb-pc087\desktop\microblog\venv\lib\site-packages\flask\app.py:1891]
Traceback (most recent call last):
  File "c:\users\zb-pc087\desktop\microblog\venv\lib\site-packages\flask\app.py", line 2446, in wsgi_app
    response = self.full_dispatch_request()
  File "c:\users\zb-pc087\desktop\microblog\venv\lib\site-packages\flask\app.py", line 1951, in full_dispatch_request
    rv = self.handle_user_exception(e)
  File "c:\users\zb-pc087\desktop\microblog\venv\lib\site-packages\flask\app.py", line 1820, in handle_user_exception
    reraise(exc_type, exc_value, tb)
  File "c:\users\zb-pc087\desktop\microblog\venv\lib\site-packages\flask\_compat.py", line 39, in reraise
    raise value
  File "c:\users\zb-pc087\desktop\microblog\venv\lib\site-packages\flask\app.py", line 1949, in full_dispatch_request
    rv = self.dispatch_request()
  File "c:\users\zb-pc087\desktop\microblog\venv\lib\site-packages\flask\app.py", line 1935, in dispatch_request
    return self.view_functions[rule.endpoint](**req.view_args)
  File "c:\users\zb-pc087\desktop\microblog\venv\lib\site-packages\flask_login\utils.py", line 261, in decorated_view
    return func(*args, **kwargs)
  File "C:\Users\ZB-PC087\Desktop\microblog\app\routes.py", line 93, in user
    posts = user.posts.order_by(Post.timestamp.desc()).paginate(
AttributeError: 'User' object has no attribute 'posts'
2019-10-17 16:34:39,605 INFO: Microblog startup [in C:\Users\ZB-PC087\Desktop\microblog\app\__init__.py:52]
2019-10-17 16:34:42,736 ERROR: Exception on /user/user1 [GET] [in c:\users\zb-pc087\desktop\microblog\venv\lib\site-packages\flask\app.py:1891]
Traceback (most recent call last):
  File "c:\users\zb-pc087\desktop\microblog\venv\lib\site-packages\flask\app.py", line 2446, in wsgi_app
    response = self.full_dispatch_request()
  File "c:\users\zb-pc087\desktop\microblog\venv\lib\site-packages\flask\app.py", line 1951, in full_dispatch_request
    rv = self.handle_user_exception(e)
  File "c:\users\zb-pc087\desktop\microblog\venv\lib\site-packages\flask\app.py", line 1820, in handle_user_exception
    reraise(exc_type, exc_value, tb)
  File "c:\users\zb-pc087\desktop\microblog\venv\lib\site-packages\flask\_compat.py", line 39, in reraise
    raise value
  File "c:\users\zb-pc087\desktop\microblog\venv\lib\site-packages\flask\app.py", line 1949, in full_dispatch_request
    rv = self.dispatch_request()
  File "c:\users\zb-pc087\desktop\microblog\venv\lib\site-packages\flask\app.py", line 1935, in dispatch_request
    return self.view_functions[rule.endpoint](**req.view_args)
  File "c:\users\zb-pc087\desktop\microblog\venv\lib\site-packages\flask_login\utils.py", line 261, in decorated_view
    return func(*args, **kwargs)
  File "C:\Users\ZB-PC087\Desktop\microblog\app\routes.py", line 93, in user
    posts = user.posts.order_by(Post.timestamp.desc()).paginate(
AttributeError: 'User' object has no attribute 'posts'
2019-10-17 16:38:23,776 INFO: Microblog startup [in C:\Users\ZB-PC087\Desktop\microblog\app\__init__.py:52]
2019-10-17 16:38:26,288 ERROR: Exception on /user/user1 [GET] [in c:\users\zb-pc087\desktop\microblog\venv\lib\site-packages\flask\app.py:1891]
Traceback (most recent call last):
  File "c:\users\zb-pc087\desktop\microblog\venv\lib\site-packages\flask\app.py", line 2446, in wsgi_app
    response = self.full_dispatch_request()
  File "c:\users\zb-pc087\desktop\microblog\venv\lib\site-packages\flask\app.py", line 1951, in full_dispatch_request
    rv = self.handle_user_exception(e)
  File "c:\users\zb-pc087\desktop\microblog\venv\lib\site-packages\flask\app.py", line 1820, in handle_user_exception
    reraise(exc_type, exc_value, tb)
  File "c:\users\zb-pc087\desktop\microblog\venv\lib\site-packages\flask\_compat.py", line 39, in reraise
    raise value
  File "c:\users\zb-pc087\desktop\microblog\venv\lib\site-packages\flask\app.py", line 1949, in full_dispatch_request
    rv = self.dispatch_request()
  File "c:\users\zb-pc087\desktop\microblog\venv\lib\site-packages\flask\app.py", line 1935, in dispatch_request
    return self.view_functions[rule.endpoint](**req.view_args)
  File "c:\users\zb-pc087\desktop\microblog\venv\lib\site-packages\flask_login\utils.py", line 261, in decorated_view
    return func(*args, **kwargs)
  File "C:\Users\ZB-PC087\Desktop\microblog\app\routes.py", line 131, in user
    posts = user.posts.order_by(Post.timestamp.desc()).paginate(
AttributeError: 'User' object has no attribute 'posts'
2019-10-17 16:41:06,261 INFO: Microblog startup [in C:\Users\ZB-PC087\Desktop\microblog\app\__init__.py:52]
2019-10-17 16:41:11,862 ERROR: Exception on /user/user1 [GET] [in c:\users\zb-pc087\desktop\microblog\venv\lib\site-packages\flask\app.py:1891]
Traceback (most recent call last):
  File "c:\users\zb-pc087\desktop\microblog\venv\lib\site-packages\flask\app.py", line 2446, in wsgi_app
    response = self.full_dispatch_request()
  File "c:\users\zb-pc087\desktop\microblog\venv\lib\site-packages\flask\app.py", line 1951, in full_dispatch_request
    rv = self.handle_user_exception(e)
  File "c:\users\zb-pc087\desktop\microblog\venv\lib\site-packages\flask\app.py", line 1820, in handle_user_exception
    reraise(exc_type, exc_value, tb)
  File "c:\users\zb-pc087\desktop\microblog\venv\lib\site-packages\flask\_compat.py", line 39, in reraise
    raise value
  File "c:\users\zb-pc087\desktop\microblog\venv\lib\site-packages\flask\app.py", line 1949, in full_dispatch_request
    rv = self.dispatch_request()
  File "c:\users\zb-pc087\desktop\microblog\venv\lib\site-packages\flask\app.py", line 1935, in dispatch_request
    return self.view_functions[rule.endpoint](**req.view_args)
  File "c:\users\zb-pc087\desktop\microblog\venv\lib\site-packages\flask_login\utils.py", line 261, in decorated_view
    return func(*args, **kwargs)
  File "C:\Users\ZB-PC087\Desktop\microblog\app\routes.py", line 93, in user
    posts = user.posts.order_by(Post.timestamp.desc()).paginate(
AttributeError: 'User' object has no attribute 'posts'
2019-10-17 16:55:41,357 INFO: Microblog startup [in C:\Users\ZB-PC087\Desktop\microblog\app\__init__.py:52]
2019-10-17 16:55:45,492 ERROR: Exception on /user/user1 [GET] [in c:\users\zb-pc087\desktop\microblog\venv\lib\site-packages\flask\app.py:1891]
Traceback (most recent call last):
  File "c:\users\zb-pc087\desktop\microblog\venv\lib\site-packages\flask\app.py", line 2446, in wsgi_app
    response = self.full_dispatch_request()
  File "c:\users\zb-pc087\desktop\microblog\venv\lib\site-packages\flask\app.py", line 1951, in full_dispatch_request
    rv = self.handle_user_exception(e)
  File "c:\users\zb-pc087\desktop\microblog\venv\lib\site-packages\flask\app.py", line 1820, in handle_user_exception
    reraise(exc_type, exc_value, tb)
  File "c:\users\zb-pc087\desktop\microblog\venv\lib\site-packages\flask\_compat.py", line 39, in reraise
    raise value
  File "c:\users\zb-pc087\desktop\microblog\venv\lib\site-packages\flask\app.py", line 1949, in full_dispatch_request
    rv = self.dispatch_request()
  File "c:\users\zb-pc087\desktop\microblog\venv\lib\site-packages\flask\app.py", line 1935, in dispatch_request
    return self.view_functions[rule.endpoint](**req.view_args)
  File "c:\users\zb-pc087\desktop\microblog\venv\lib\site-packages\flask_login\utils.py", line 261, in decorated_view
    return func(*args, **kwargs)
  File "C:\Users\ZB-PC087\Desktop\microblog\app\routes.py", line 93, in user
    posts = user.posts.order_by(Post.timestamp.desc()).paginate(
AttributeError: 'User' object has no attribute 'posts'
2019-10-17 16:56:14,501 ERROR: Exception on /user/email [GET] [in c:\users\zb-pc087\desktop\microblog\venv\lib\site-packages\flask\app.py:1891]
Traceback (most recent call last):
  File "c:\users\zb-pc087\desktop\microblog\venv\lib\site-packages\flask\app.py", line 2446, in wsgi_app
    response = self.full_dispatch_request()
  File "c:\users\zb-pc087\desktop\microblog\venv\lib\site-packages\flask\app.py", line 1951, in full_dispatch_request
    rv = self.handle_user_exception(e)
  File "c:\users\zb-pc087\desktop\microblog\venv\lib\site-packages\flask\app.py", line 1820, in handle_user_exception
    reraise(exc_type, exc_value, tb)
  File "c:\users\zb-pc087\desktop\microblog\venv\lib\site-packages\flask\_compat.py", line 39, in reraise
    raise value
  File "c:\users\zb-pc087\desktop\microblog\venv\lib\site-packages\flask\app.py", line 1949, in full_dispatch_request
    rv = self.dispatch_request()
  File "c:\users\zb-pc087\desktop\microblog\venv\lib\site-packages\flask\app.py", line 1935, in dispatch_request
    return self.view_functions[rule.endpoint](**req.view_args)
  File "c:\users\zb-pc087\desktop\microblog\venv\lib\site-packages\flask_login\utils.py", line 261, in decorated_view
    return func(*args, **kwargs)
  File "C:\Users\ZB-PC087\Desktop\microblog\app\routes.py", line 93, in user
    posts = user.posts.order_by(Post.timestamp.desc()).paginate(
AttributeError: 'User' object has no attribute 'posts'
